<?xml version="1.0" ?>
<!-- =================================================================================== -->
<!-- |    This document was autogenerated by xacro from robot.xacro                    | -->
<!-- |    EDITING THIS FILE BY HAND IS NOT RECOMMENDED                                 | -->
<!-- =================================================================================== -->
<robot name="fiveages_cr5_dual_station">
  <link name="base_link">
    <visual>
      <geometry>
        <mesh filename="package://cr5_dual_description/meshes/base.obj"/>
      </geometry>
    </visual>
    <!-- 横着的圆柱体：连接左右手臂的横梁 -->
    <collision>
      <origin rpy="1.5708 0 0" xyz="0 0 0.625"/>
      <geometry>
        <cylinder length="0.37" radius="0.1"/>
      </geometry>
    </collision>
    <!-- 直立的圆柱体：中间立柱 -->
    <collision>
      <origin rpy="0 0 0" xyz="0 0 0.4"/>
      <geometry>
        <cylinder length="0.9" radius="0.1"/>
      </geometry>
    </collision>

    <collision>
      <origin rpy="0 0 0" xyz="0.05 0.03 0.88"/>
      <geometry>
        <box size="0.15 0.2 0.1"/>
      </geometry>
    </collision>
    <!-- 地面collision -->
    <collision>
      <origin xyz="0 0 -0.1"/>
      <geometry>
        <box size="3 3 0.05"/>
      </geometry>
    </collision>
  </link>
  <link name="left_base_link">
    <inertial>
      <origin xyz="-8.0961E-06 0.0019103 0.028995"/>
      <mass value="0.90882"/>
      <inertia ixx="0.0014545" ixy="4.2968E-08" ixz="-1.8199E-07" iyy="0.001345" iyz="-6.243E-06" izz="0.002155"/>
    </inertial>
    <visual>
      <geometry>
        <mesh filename="package://cr5_description/meshes/visual/base_link.obj"/>
      </geometry>
    </visual>
    <collision>
      <origin xyz="0 0 0.05"/>
      <geometry>
        <cylinder length="0.1" radius="0.1"/>
      </geometry>
    </collision>
  </link>
  <link name="left_Link1">
    <inertial>
      <origin xyz="-8.7268E-07 -0.0032576 -0.0076748"/>
      <mass value="1.6123"/>
      <inertia ixx="0.0029122" ixy="5.7387E-09" ixz="1.9945E-08" iyy="0.0028191" iyz="0.00044094" izz="0.0032836"/>
    </inertial>
    <visual>
      <geometry>
        <mesh filename="package://cr5_description/meshes/visual/Link1.obj"/>
      </geometry>
    </visual>
    <collision>
      <geometry>
        <cylinder length="0.17" radius="0.08"/>
      </geometry>
    </collision>
  </link>
  <joint name="left_joint1" type="revolute">
    <origin xyz="0 0 0.147"/>
    <parent link="left_base_link"/>
    <child link="left_Link1"/>
    <axis xyz="0 0 1"/>
    <limit effort="300" lower="-6.283185307179586" upper="6.283185307179586" velocity="3.141592653589793"/>
  </joint>
  <link name="left_Link2">
    <inertial>
      <origin xyz="-0.21351 -1.3842E-06 0.14252"/>
      <mass value="5.5186"/>
      <inertia ixx="0.0085919" ixy="7.5552E-07" ixz="-7.8922E-07" iyy="0.027553" iyz="1.4629E-07" izz="0.028294"/>
    </inertial>
    <visual>
      <geometry>
        <mesh filename="package://cr5_description/meshes/visual/Link2.obj"/>
      </geometry>
    </visual>
    <collision>
      <origin rpy="0 0 0" xyz="0 0 0.145"/>
      <geometry>
        <cylinder length="0.18" radius="0.07"/>
      </geometry>
    </collision>
    <collision>
      <origin rpy="0 1.5707963267948966 0" xyz="-0.2 0 0.15"/>
      <geometry>
        <cylinder length="0.43" radius="0.065"/>
      </geometry>
    </collision>
    <collision>
      <origin xyz="-0.43 0 0.145"/>
      <geometry>
        <cylinder length="0.18" radius="0.07"/>
      </geometry>
    </collision>
  </link>
  <joint name="left_joint2" type="revolute">
    <origin rpy="1.5707963267948966 1.5707963267948966 0"/>
    <parent link="left_Link1"/>
    <child link="left_Link2"/>
    <axis xyz="0 0 1"/>
    <limit effort="300" lower="-6.283185307179586" upper="6.283185307179586" velocity="3.141592653589793"/>
  </joint>
  <link name="left_Link3">
    <inertial>
      <origin xyz="-0.15231 -1.4079E-07 0.022693"/>
      <mass value="2.8536"/>
      <inertia ixx="0.0032608" ixy="-3.2147E-10" ixz="0.00012363" iyy="0.0092967" iyz="2.9478E-10" izz="0.0095552"/>
    </inertial>
    <visual>
      <geometry>
        <mesh filename="package://cr5_description/meshes/visual/Link3.obj"/>
      </geometry>
    </visual>
    <collision>
      <origin xyz="0 0 0.02"/>
      <geometry>
        <cylinder length="0.15" radius="0.07"/>
      </geometry>
    </collision>
    <collision>
      <origin rpy="0 1.5707963267948966 0" xyz="-0.2 0 0.03"/>
      <geometry>
        <cylinder length="0.26" radius="0.05"/>
      </geometry>
    </collision>
    <collision>
      <origin xyz="-0.355 0 0.02"/>
      <geometry>
        <cylinder length="0.15" radius="0.05"/>
      </geometry>
    </collision>
  </link>
  <joint name="left_joint3" type="revolute">
    <origin xyz="-0.427 0 0"/>
    <parent link="left_Link2"/>
    <child link="left_Link3"/>
    <axis xyz="0 0 1"/>
    <limit effort="300" lower="-2.7925" upper="2.7925" velocity="3.14159"/>
  </joint>
  <link name="left_Link4">
    <inertial>
      <origin xyz="-3.2386E-07 -0.002077 -0.0015548"/>
      <mass value="0.67058"/>
      <inertia ixx="0.00066939" ixy="4.1975E-10" ixz="-1.0734E-08" iyy="0.00065424" iyz="0.00011081" izz="0.00065365"/>
    </inertial>
    <visual>
      <geometry>
        <mesh filename="package://cr5_description/meshes/visual/Link4.obj"/>
      </geometry>
    </visual>
    <collision>
      <origin rpy="1.5707963267948966 0 0"/>
      <geometry>
        <cylinder length="0.155" radius="0.055"/>
      </geometry>
    </collision>
  </link>
  <joint name="left_joint4" type="revolute">
    <origin rpy="0 0 -1.5707963267948966" xyz="-0.357 0 0.141"/>
    <parent link="left_Link3"/>
    <child link="left_Link4"/>
    <axis xyz="0 0 1"/>
    <limit effort="300" lower="-6.283185307179586" upper="6.283185307179586" velocity="3.141592653589793"/>
  </joint>
  <link name="left_Link5">
    <inertial>
      <origin xyz="-3.7738E-07 -0.0045777 -0.0012971"/>
      <mass value="0.7269"/>
      <inertia ixx="0.00073069" ixy="-5.7806E-09" ixz="6.7132E-09" iyy="0.00071195" iyz="-0.00011926" izz="0.00071391"/>
    </inertial>
    <visual>
      <geometry>
        <mesh filename="package://cr5_description/meshes/visual/Link5.obj"/>
      </geometry>
    </visual>
    <collision>
      <origin rpy="1.5707963267948966 0 0"/>
      <geometry>
        <cylinder length="0.18" radius="0.055"/>
      </geometry>
    </collision>
  </link>
  <joint name="left_joint5" type="revolute">
    <origin rpy="1.5707963267948966 0 0" xyz="0 -0.116 0"/>
    <parent link="left_Link4"/>
    <child link="left_Link5"/>
    <axis xyz="0 0 1"/>
    <limit effort="300" lower="-6.283185307179586" upper="6.283185307179586" velocity="3.141592653589793"/>
  </joint>
  <link name="left_Link6">
    <inertial>
      <origin xyz="5.0777E-11 9.3774E-05 -0.019285"/>
      <mass value="0.15789"/>
      <inertia ixx="7.8045E-05" ixy="6.1582E-15" ixz="6.2471E-14" iyy="7.9168E-05" iyz="-1.3822E-07" izz="0.00012951"/>
    </inertial>
    <visual>
      <geometry>
        <mesh filename="package://cr5_description/meshes/visual/Link6.obj"/>
      </geometry>
    </visual>
    <collision>
      <origin xyz="0 0 0.07"/>
      <geometry>
        <box size="0.08 0.08 0.14"/>
      </geometry>
    </collision>
    <collision>
      <origin xyz="0 0 0.21"/>
      <geometry>
        <box size="0.18 0.04 0.04"/>
      </geometry>
    </collision>
  </link>
  <joint name="left_joint6" type="revolute">
    <origin rpy="-1.5707963267948966 0 0" xyz="0 0.105 0"/>
    <parent link="left_Link5"/>
    <child link="left_Link6"/>
    <axis xyz="0 0 1"/>
    <limit effort="300" lower="-6.283185307179586" upper="6.283185307179586" velocity="3.141592653589793"/>
  </joint>
  <link name="right_base_link">
    <inertial>
      <origin xyz="-8.0961E-06 0.0019103 0.028995"/>
      <mass value="0.90882"/>
      <inertia ixx="0.0014545" ixy="4.2968E-08" ixz="-1.8199E-07" iyy="0.001345" iyz="-6.243E-06" izz="0.002155"/>
    </inertial>
    <visual>
      <geometry>
        <mesh filename="package://cr5_description/meshes/visual/base_link.obj"/>
      </geometry>
    </visual>
    <collision>
      <origin xyz="0 0 0.05"/>
      <geometry>
        <cylinder length="0.1" radius="0.1"/>
      </geometry>
    </collision>
  </link>
  <link name="right_Link1">
    <inertial>
      <origin xyz="-8.7268E-07 -0.0032576 -0.0076748"/>
      <mass value="1.6123"/>
      <inertia ixx="0.0029122" ixy="5.7387E-09" ixz="1.9945E-08" iyy="0.0028191" iyz="0.00044094" izz="0.0032836"/>
    </inertial>
    <visual>
      <geometry>
        <mesh filename="package://cr5_description/meshes/visual/Link1.obj"/>
      </geometry>
    </visual>
    <collision>
      <geometry>
        <cylinder length="0.17" radius="0.08"/>
      </geometry>
    </collision>
  </link>
  <joint name="right_joint1" type="revolute">
    <origin xyz="0 0 0.147"/>
    <parent link="right_base_link"/>
    <child link="right_Link1"/>
    <axis xyz="0 0 1"/>
    <limit effort="300" lower="-6.283185307179586" upper="6.283185307179586" velocity="3.141592653589793"/>
  </joint>
  <link name="right_Link2">
    <inertial>
      <origin xyz="-0.21351 -1.3842E-06 0.14252"/>
      <mass value="5.5186"/>
      <inertia ixx="0.0085919" ixy="7.5552E-07" ixz="-7.8922E-07" iyy="0.027553" iyz="1.4629E-07" izz="0.028294"/>
    </inertial>
    <visual>
      <geometry>
        <mesh filename="package://cr5_description/meshes/visual/Link2.obj"/>
      </geometry>
    </visual>
    <collision>
      <origin rpy="0 0 0" xyz="0 0 0.145"/>
      <geometry>
        <cylinder length="0.18" radius="0.07"/>
      </geometry>
    </collision>
    <collision>
      <origin rpy="0 1.5707963267948966 0" xyz="-0.2 0 0.15"/>
      <geometry>
        <cylinder length="0.43" radius="0.065"/>
      </geometry>
    </collision>
    <collision>
      <origin xyz="-0.43 0 0.145"/>
      <geometry>
        <cylinder length="0.18" radius="0.07"/>
      </geometry>
    </collision>
  </link>
  <joint name="right_joint2" type="revolute">
    <origin rpy="1.5707963267948966 1.5707963267948966 0"/>
    <parent link="right_Link1"/>
    <child link="right_Link2"/>
    <axis xyz="0 0 1"/>
    <limit effort="300" lower="-6.283185307179586" upper="6.283185307179586" velocity="3.141592653589793"/>
  </joint>
  <link name="right_Link3">
    <inertial>
      <origin xyz="-0.15231 -1.4079E-07 0.022693"/>
      <mass value="2.8536"/>
      <inertia ixx="0.0032608" ixy="-3.2147E-10" ixz="0.00012363" iyy="0.0092967" iyz="2.9478E-10" izz="0.0095552"/>
    </inertial>
    <visual>
      <geometry>
        <mesh filename="package://cr5_description/meshes/visual/Link3.obj"/>
      </geometry>
    </visual>
    <collision>
      <origin xyz="0 0 0.02"/>
      <geometry>
        <cylinder length="0.15" radius="0.07"/>
      </geometry>
    </collision>
    <collision>
      <origin rpy="0 1.5707963267948966 0" xyz="-0.2 0 0.03"/>
      <geometry>
        <cylinder length="0.26" radius="0.05"/>
      </geometry>
    </collision>
    <collision>
      <origin xyz="-0.355 0 0.02"/>
      <geometry>
        <cylinder length="0.15" radius="0.05"/>
      </geometry>
    </collision>
  </link>
  <joint name="right_joint3" type="revolute">
    <origin xyz="-0.427 0 0"/>
    <parent link="right_Link2"/>
    <child link="right_Link3"/>
    <axis xyz="0 0 1"/>
    <limit effort="300" lower="-2.7925" upper="2.7925" velocity="3.14159"/>
  </joint>
  <link name="right_Link4">
    <inertial>
      <origin xyz="-3.2386E-07 -0.002077 -0.0015548"/>
      <mass value="0.67058"/>
      <inertia ixx="0.00066939" ixy="4.1975E-10" ixz="-1.0734E-08" iyy="0.00065424" iyz="0.00011081" izz="0.00065365"/>
    </inertial>
    <visual>
      <geometry>
        <mesh filename="package://cr5_description/meshes/visual/Link4.obj"/>
      </geometry>
    </visual>
    <collision>
      <origin rpy="1.5707963267948966 0 0"/>
      <geometry>
        <cylinder length="0.155" radius="0.055"/>
      </geometry>
    </collision>
  </link>
  <joint name="right_joint4" type="revolute">
    <origin rpy="0 0 -1.5707963267948966" xyz="-0.357 0 0.141"/>
    <parent link="right_Link3"/>
    <child link="right_Link4"/>
    <axis xyz="0 0 1"/>
    <limit effort="300" lower="-6.283185307179586" upper="6.283185307179586" velocity="3.141592653589793"/>
  </joint>
  <link name="right_Link5">
    <inertial>
      <origin xyz="-3.7738E-07 -0.0045777 -0.0012971"/>
      <mass value="0.7269"/>
      <inertia ixx="0.00073069" ixy="-5.7806E-09" ixz="6.7132E-09" iyy="0.00071195" iyz="-0.00011926" izz="0.00071391"/>
    </inertial>
    <visual>
      <geometry>
        <mesh filename="package://cr5_description/meshes/visual/Link5.obj"/>
      </geometry>
    </visual>
    <collision>
      <origin rpy="1.5707963267948966 0 0"/>
      <geometry>
        <cylinder length="0.18" radius="0.055"/>
      </geometry>
    </collision>
  </link>
  <joint name="right_joint5" type="revolute">
    <origin rpy="1.5707963267948966 0 0" xyz="0 -0.116 0"/>
    <parent link="right_Link4"/>
    <child link="right_Link5"/>
    <axis xyz="0 0 1"/>
    <limit effort="300" lower="-6.283185307179586" upper="6.283185307179586" velocity="3.141592653589793"/>
  </joint>
  <link name="right_Link6">
    <inertial>
      <origin xyz="5.0777E-11 9.3774E-05 -0.019285"/>
      <mass value="0.15789"/>
      <inertia ixx="7.8045E-05" ixy="6.1582E-15" ixz="6.2471E-14" iyy="7.9168E-05" iyz="-1.3822E-07" izz="0.00012951"/>
    </inertial>
    <visual>
      <geometry>
        <mesh filename="package://cr5_description/meshes/visual/Link6.obj"/>
      </geometry>
    </visual>
    <collision>
      <origin xyz="0 0 0.07"/>
      <geometry>
        <box size="0.08 0.08 0.14"/>
      </geometry>
    </collision>
    <collision>
      <origin xyz="0 0 0.21"/>
      <geometry>
        <box size="0.18 0.04 0.04"/>
      </geometry>
    </collision>
  </link>
  <joint name="right_joint6" type="revolute">
    <origin rpy="-1.5707963267948966 0 0" xyz="0 0.105 0"/>
    <parent link="right_Link5"/>
    <child link="right_Link6"/>
    <axis xyz="0 0 1"/>
    <limit effort="300" lower="-6.283185307179586" upper="6.283185307179586" velocity="3.141592653589793"/>
  </joint>
  <!-- Initial guess; measure or adjust in RViz for final mounting pose -->
  <joint name="left_arm_mount" type="fixed">
    <origin rpy="0 1.3963 1.5708" xyz="0.0 0.185 0.625"/>
    <parent link="base_link"/>
    <child link="left_base_link"/>
  </joint>
  <joint name="right_arm_mount" type="fixed">
    <origin rpy="0 -1.3963 1.5708" xyz="0.0 -0.185 0.625"/>
    <parent link="base_link"/>
    <child link="right_base_link"/>
  </joint>
  <!-- Camera TF from obj file analysis -->
  <link name="camera_link"/>
  <joint name="camera_mount" type="fixed">
    <origin rpy="0 0.7854 0" xyz="0.0918 -0.0215 0.8291"/>
    <parent link="base_link"/>
    <child link="camera_link"/>
  </joint>

  <!-- Left TCP (Tool Center Point) frame -->
  <link name="left_tcp">
  </link>
  <joint name="left_tcp_joint" type="fixed">
    <origin xyz="0 0 0.21"/>
    <parent link="left_Link6"/>
    <child link="left_tcp"/>
  </joint>

  <!-- Right TCP (Tool Center Point) frame -->
  <link name="right_tcp">
  </link>
  <joint name="right_tcp_joint" type="fixed">
    <origin xyz="0 0 0.21"/>
    <parent link="right_Link6"/>
    <child link="right_tcp"/>
  </joint>
</robot>
